<?xml version="1.0" ?>
<robot name="cancellor">
  <link name="basex">
    <visual>
      <origin xyz="0 0 0"/>
    </visual>
  </link>
  <link name="basey">
    <visual>
      <origin xyz="0 0 0"/>
    </visual>
  </link>
  <joint name="move_x" type="prismatic">
    <origin rpy="0 0 0" xyz="0.0 0 0.0"/>
    <parent link="basex"/>
    <child link="basey"/>
    <axis xyz="1 0 0"/>
    <limit effort="1000.0" lower="-10000000" upper="10000000" velocity="100"/>
  </joint>
  <joint name="move_y" type="prismatic">
    <origin rpy="0 0 0" xyz="0.0 0.0 0.0"/>
    <parent link="basey"/>
    <child link="base_link"/>
    <axis xyz="0 1 0"/>
    <limit effort="1000.0" lower="-10000000" upper="10000000" velocity="100"/>
  </joint>

  <link name="base_link">
    <inertial>
      <origin xyz="8.06501835494806E-11 -0.0338780544641589 -6.13519647304395E-10" rpy="0 0 0" />
      <mass value="0.0365925774909924" />
      <inertia ixx="1.14555538013607E-05" ixy="1.40790430797004E-13" ixz="-3.85235521580481E-14" iyy="5.37588411827752E-06" iyz="-1.17698572171165E-13" izz="1.14526674484253E-05" />
    </inertial>
    <visual>
      <origin xyz="0 0 0" rpy="0 0 0" />
      <geometry>
        <mesh filename="/home/biorobotics/IsaacGym_Tutorial/assets/cancellor/meshes/base_link.STL" />
      </geometry>
      <material name="">
        <color rgba="1 1 1 0.4" />
      </material>
    </visual>
    <collision>
      <origin xyz="0 0 0" rpy="0 0 0" />
      <geometry>
        <mesh filename="/home/biorobotics/IsaacGym_Tutorial/assets/cancellor/meshes/base_link.STL" />
      </geometry>
    </collision>
  </link>
  <link name="end_link">
    <inertial>
      <origin xyz="5.39151995586174E-09 2.48615892588212E-09 0.0139122030459944" rpy="0 0 0" />
      <mass value="0.000930041634459067" />
      <inertia ixx="1.84743464948672E-07" ixy="1.91778613439961E-15" ixz="3.6797273718863E-14" iyy="1.84743477463938E-07" iyz="1.74269088454371E-14" izz="1.15847934315868E-08" />
    </inertial>
    <visual>
      <origin xyz="0 0 0" rpy="0 0 0" />
      <geometry>
        <mesh filename="/home/biorobotics/IsaacGym_Tutorial/assets/cancellor/meshes/end_link.STL" />
      </geometry>
      <material name="">
        <color rgba="1 1 1 0.7" />
      </material>
    </visual>
    <collision>
      <origin xyz="0 0 0" rpy="0 0 0" />
      <geometry>
        <mesh filename="/home/biorobotics/IsaacGym_Tutorial/assets/cancellor/meshes/end_link.STL" />
      </geometry>
    </collision>
  </link>

  <link name="tip">
    <visual>
      <origin xyz="5.39151995586174E-09 2.48615892588212E-09 0.0139122030459944" rpy="0 0 0" />
    </visual>
  </link>
  <joint name="tip_x" type="prismatic">
    <origin xyz="0 0 0.007" rpy="0 0 0" />
    <parent link="base_link"/>
    <child link="tip"/>
    <axis xyz="1 0 0"/>
    <limit effort="20000000" lower="-10000000" upper="10000000" velocity="1.3"/>
  </joint>


  <joint name="tip_y" type="prismatic">
    <origin xyz="0 0 0" rpy="0 0 0" />
    <parent link="tip" />
    <child link="end_link" />
    <axis xyz="0 1 0" />
  </joint>
</robot>